Workbook

Sheet dim_respondents.csv
A1: Respondent_ID | B1: Name | C1: Age | D1: Gender | E1: City_ID | F1: Tier | G1: Brands
A2: 120031 | B2: Aniruddh Issac | C2: 15-18 | D2: F | E2: CT117 | F2: =VLOOKUP(E2,dim_cities!$A$1:$C$11,3) -> Tier 2 | G2: =VLOOKUP(A2,fact_survey_responses!$B$1:$F$71,2) -> Blue Bull
A3: 120032 | B3: Trisha Rout | C3: 19-30 | D3: M | E3: CT118 | F3: =VLOOKUP(E3,dim_cities!$A$1:$C$11,3) -> Tier 2 | G3: =VLOOKUP(A3,fact_survey_responses!$B$1:$F$71,2) -> Bepsi
A4: 120033 | B4: Yuvraj Virk | C4: 15-18 | D4: M | E4: CT116 | F4: =VLOOKUP(E4,dim_cities!$A$1:$C$11,3) -> Tier 1 | G4: =VLOOKUP(A4,fact_survey_responses!$B$1:$F$71,2) -> Bepsi
A5: 120034 | B5: Pranay Chand | C5: 31-45 | D5: F | E5: CT113 | F5: =VLOOKUP(E5,dim_cities!$A$1:$C$11,3) -> Tier 1 | G5: =VLOOKUP(A5,fact_survey_responses!$B$1:$F$71,2) -> Bepsi
A6: 120035 | B6: Mohanlal Joshi | C6: 19-30 | D6: F | E6: CT120 | F6: =VLOOKUP(E6,dim_cities!$A$1:$C$11,3) -> Tier 2 | G6: =VLOOKUP(A6,fact_survey_responses!$B$1:$F$71,2) -> Sky 9
A7: 120036 | B7: Zeeshan Ratta | C7: 19-30 | D7: F | E7: CT118 | F7: =VLOOKUP(E7,dim_cities!$A$1:$C$11,3) -> Tier 2 | G7: =VLOOKUP(A7,fact_survey_responses!$B$1:$F$71,2) -> Cola-Coka
A8: 120037 | B8: Oorja Anne | C8: 19-30 | D8: M | E8: CT112 | F8: =VLOOKUP(E8,dim_cities!$A$1:$C$11,3) -> Tier 1 | G8: =VLOOKUP(A8,fact_survey_responses!$B$1:$F$71,2) -> Cola-Coka
A9: 120038 | B9: Rhea Khanna | C9: 19-30 | D9: M | E9: CT116 | F9: =VLOOKUP(E9,dim_cities!$A$1:$C$11,3) -> Tier 1 | G9: =VLOOKUP(A9,fact_survey_responses!$B$1:$F$71,2) -> Gangster
A10: 120039 | B10: Zara Joshi | C10: 46-65 | D10: M | E10: CT116 | F10: =VLOOKUP(E10,dim_cities!$A$1:$C$11,3) -> Tier 1 | G10: =VLOOKUP(A10,fact_survey_responses!$B$1:$F$71,2) -> Gangster
A11: 120040 | B11: Sana Dhawan | C11: 19-30 | D11: F | E11: CT116 | F11: =VLOOKUP(E11,dim_cities!$A$1:$C$11,3) -> Tier 1 | G11: =VLOOKUP(A11,fact_survey_responses!$B$1:$F$71,2) -> Sky 9
A12: 120041 | B12: Misha Warrior | C12: 19-30 | D12: F | E12: CT113 | F12: =VLOOKUP(E12,dim_cities!$A$1:$C$11,3) -> Tier 1 | G12: =VLOOKUP(A12,fact_survey_responses!$B$1:$F$71,2) -> Codex
A13: 120042 | B13: Kiara Chander | C13: 19-30 | D13: F | E13: CT112 | F13: =VLOOKUP(E13,dim_cities!$A$1:$C$11,3) -> Tier 1 | G13: =VLOOKUP(A13,fact_survey_responses!$B$1:$F$71,2) -> Others
... A71: 120100 | B71: Divyansh Bhatt | C71: 19-30 | D71: M | E71: CT114 | F71: =VLOOKUP(E71,dim_cities!$A$1:$C$11,3) -> Tier 1 | G71: =VLOOKUP(A71,fact_survey_responses!$B$1:$F$71,2) -> Gangster

Sheet dim_cities
A1: City_ID | B1: City | C1: Tier
A2: CT111 | B2: DELHI | C2: Tier 1
A3: CT112 | B3: MUMBAI | C3: Tier 1
A4: CT113 | B4: Bangalore | C4: Tier 1
A5: CT114 | B5: CHENNAI | C5: Tier 1
A6: CT115 | B6: Kolkata | C6: Tier 2
A7: CT116 | B7: Hyderabad | C7: Tier 1
A8: CT117 | B8: Ahmedabad | C8: Tier 2
A9: CT118 | B9: Pune | C9: Tier 2
A10: CT119 | B10: Jaipur | C10: Tier 2
A11: CT120 | B11: LUCKNOW | C11: Tier 2

Sheet fact_survey_responses
A1: Response_ID | B1: Respondent_ID | C1: Current_brands | D1: Taste_experience | E1: Price_range | F1: Purchase_location
A2: 103001 | B2: 120031 | C2: Blue Bull | D2: 5 | E2: 50-99 | F2: Supermarkets
A3: 103002 | B3: 120032 | C3: Bepsi | D3: 5 | E3: 50-99 | F3: Supermarkets
A4: 103003 | B4: 120033 | C4: Bepsi | D4: 2 | E4: 100-150 | F4: Supermarkets
A5: 103004 | B5: 120034 | C5: Bepsi | D5: 5 | E5: Above 150 | F5: Supermarkets
A6: 103005 | B6: 120035 | C6: Sky 9 | D6: 5 | E6: 100-150 | F6: Online retailers
A7: 103006 | B7: 120036 | C7: Cola-Coka | D7: 5 | E7: Above 150 | F7: Gyms and fitness centers
A8: 103007 | B8: 120037 | C8: Cola-Coka | D8: 4 | E8: 100-150 | F8: Other
A9: 103008 | B9: 120038 | C9: Gangster | D9: 4 | E9: 50-99 | F9: Gyms and fitness centers
A10: 103009 | B10: 120039 | C10: Gangster | D10: 3 | E10: 100-150 | F10: Other
A11: 103010 | B11: 120040 | C11: Sky 9 | D11: 4 | E11: 50-99 | F11: Gyms and fitness centers
A12: 103011 | B12: 120041 | C12: Codex | D12: 5 | E12: 50-99 | F12: Supermarkets
A13: 103012 | B13: 120042 | C13: Others | D13: 2 | E13: 100-150 | F13: Online retailers
... A71: 103070 | B71: 120100 | C71: Gangster | D71: 2 | E71: 50-99 | F71: Gyms and fitness centers

Sheet Analysis
A1: Consumer Survey Analysis
A5: Distribution of respondents across city tiers
A7: Tier | B7: COUNT of Respondent_ID
A8: Tier 1 | B8: 50
A9: Tier 2 | B9: 20
A10: Grand Total | B10: 70
A12: Gender distribution of respondents by age group
A14: COUNT of Respondent_ID | B14: Age
A15: Gender | B15: 15-18 | C15: 19-30 | D15: 31-45 | E15: 46-65 | F15: 65+ | G15: Grand Total
A16: F | B16: 5 | C16: 13 | D16: 7 | G16: 25
A17: M | B17: 4 | C17: 29 | D17: 4 | E17: 1 | F17: 2 | G17: 40
A18: Non-binary | B18: 1 | D18: 3 | E18: 1 | G18: 5
A19: Grand Total | B19: 10 | C19: 42 | D19: 14 | E19: 2 | F19: 2 | G19: 70
A21: Highest average taste experience rating by brand
A23: Current_brands | B23: AVERAGE of Taste_experience
A24: Bepsi | B24: 3.2777778
A25: Blue Bull | B25: 3
A26: Codex | B26: 3.5
A27: Cola-Coka | B27: 3.2
A28: Gangster | B28: 3.0833333
A29: Others | B29: 3
A30: Sky 9 | B30: 3.8571429
A31: Grand Total | B31: 3.2571429 | C31: Average taste experience rating across all brands
A33: Average taste experience rating by purchase location
A35: Purchase_location | B35: AVERAGE of Taste_experience
A36: Gyms and fitness centers | B36: 3.2
A37: Local stores | B37: 4 | C37: Highest
A38: Online retailers | B38: 2.6428571 | C38: Lowest
A39: Other | B39: 3
A40: Supermarkets | B40: 3.5588235
A41: Grand Total | B41: 3.2571429
A43: Most preferred brand among respondents aged 19-30
A45: COUNT of Respondent_ID | B45: Age
A46: Brands | B46: 15-18 | C46: 19-30 | D46: 31-45 | E46: 46-65 | F46: 65+ | G46: Grand Total
A47: Bepsi | B47: 5 | C47: 7 | D47: 5 | F47: 1 | G47: 18
A48: Blue Bull | B48: 3 | C48: 2 | D48: 2 | G48: 7
A49: Codex | C49: 5 | D49: 1 | G49: 6
A50: Cola-Coka | C50: 10 | D50: 4 | F50: 1 | G50: 15
A51: Gangster | B51: 2 | C51: 8 | D51: 1 | E51: 1 | G51: 12
A52: Others | C52: 4 | D52: 1 | G52: 5
...
